[2024-02-10T02:24:12.892+0000] {taskinstance.py:1956} INFO - Dependencies all met for dep_context=non-requeueable deps ti=<TaskInstance: censoEnade.extract_zip_file manual__2024-02-10T02:23:40.726781+00:00 [queued]>
[2024-02-10T02:24:12.907+0000] {taskinstance.py:1956} INFO - Dependencies all met for dep_context=requeueable deps ti=<TaskInstance: censoEnade.extract_zip_file manual__2024-02-10T02:23:40.726781+00:00 [queued]>
[2024-02-10T02:24:12.908+0000] {taskinstance.py:2170} INFO - Starting attempt 1 of 1
[2024-02-10T02:24:12.929+0000] {taskinstance.py:2191} INFO - Executing <Task(PythonOperator): extract_zip_file> on 2024-02-10 02:23:40.726781+00:00
[2024-02-10T02:24:12.939+0000] {standard_task_runner.py:60} INFO - Started process 748 to run task
[2024-02-10T02:24:12.943+0000] {standard_task_runner.py:87} INFO - Running: ['***', 'tasks', 'run', 'censoEnade', 'extract_zip_file', 'manual__2024-02-10T02:23:40.726781+00:00', '--job-id', '139', '--raw', '--subdir', 'DAGS_FOLDER/censoEnade.py', '--cfg-path', '/tmp/tmpgqy5hlo4']
[2024-02-10T02:24:12.948+0000] {standard_task_runner.py:88} INFO - Job 139: Subtask extract_zip_file
[2024-02-10T02:24:13.032+0000] {task_command.py:423} INFO - Running <TaskInstance: censoEnade.extract_zip_file manual__2024-02-10T02:23:40.726781+00:00 [running]> on host 366ff31d219b
[2024-02-10T02:24:13.146+0000] {taskinstance.py:2480} INFO - Exporting env vars: AIRFLOW_CTX_DAG_OWNER='NÃ©fi Fernandes' AIRFLOW_CTX_DAG_ID='censoEnade' AIRFLOW_CTX_TASK_ID='extract_zip_file' AIRFLOW_CTX_EXECUTION_DATE='2024-02-10T02:23:40.726781+00:00' AIRFLOW_CTX_TRY_NUMBER='1' AIRFLOW_CTX_DAG_RUN_ID='manual__2024-02-10T02:23:40.726781+00:00'
[2024-02-10T02:24:13.150+0000] {taskinstance.py:2698} ERROR - Task failed with exception
Traceback (most recent call last):
  File "/home/airflow/.local/lib/python3.8/site-packages/airflow/models/taskinstance.py", line 433, in _execute_task
    result = execute_callable(context=context, **execute_callable_kwargs)
  File "/home/airflow/.local/lib/python3.8/site-packages/airflow/operators/python.py", line 199, in execute
    return_value = self.execute_callable()
  File "/home/airflow/.local/lib/python3.8/site-packages/airflow/operators/python.py", line 216, in execute_callable
    return self.python_callable(*self.op_args, **self.op_kwargs)
  File "/opt/airflow/dags/censoEnade.py", line 62, in extract_zip_file
    with zipfile.SevenZipFile(zip_file_path, 'r') as zip_ref:
AttributeError: module 'zipfile' has no attribute 'SevenZipFile'
[2024-02-10T02:24:13.163+0000] {taskinstance.py:1138} INFO - Marking task as FAILED. dag_id=censoEnade, task_id=extract_zip_file, execution_date=20240210T022340, start_date=20240210T022412, end_date=20240210T022413
[2024-02-10T02:24:13.183+0000] {standard_task_runner.py:107} ERROR - Failed to execute job 139 for task extract_zip_file (module 'zipfile' has no attribute 'SevenZipFile'; 748)
[2024-02-10T02:24:13.200+0000] {local_task_job_runner.py:234} INFO - Task exited with return code 1
[2024-02-10T02:24:13.233+0000] {taskinstance.py:3280} INFO - 0 downstream tasks scheduled from follow-on schedule check
