[2024-02-11T00:00:02.734+0000] {scheduler_job_runner.py:781} ERROR - Executor reports task instance <TaskInstance: censoEnade.extract_censo_2021 scheduled__2024-02-10T00:00:00+00:00 [queued]> finished (success) although the task says it's queued. (Info: None) Was the task killed externally?
