[2024-02-11T01:22:53.537+0000] {taskinstance.py:1956} INFO - Dependencies all met for dep_context=non-requeueable deps ti=<TaskInstance: censoEnade.convert_xlsx_to_csv manual__2024-02-11T01:22:44.901787+00:00 [queued]>
[2024-02-11T01:22:53.547+0000] {taskinstance.py:1956} INFO - Dependencies all met for dep_context=requeueable deps ti=<TaskInstance: censoEnade.convert_xlsx_to_csv manual__2024-02-11T01:22:44.901787+00:00 [queued]>
[2024-02-11T01:22:53.548+0000] {taskinstance.py:2170} INFO - Starting attempt 1 of 1
[2024-02-11T01:22:53.568+0000] {taskinstance.py:2191} INFO - Executing <Task(PythonOperator): convert_xlsx_to_csv> on 2024-02-11 01:22:44.901787+00:00
[2024-02-11T01:22:53.574+0000] {standard_task_runner.py:60} INFO - Started process 458 to run task
[2024-02-11T01:22:53.577+0000] {standard_task_runner.py:87} INFO - Running: ['***', 'tasks', 'run', 'censoEnade', 'convert_xlsx_to_csv', 'manual__2024-02-11T01:22:44.901787+00:00', '--job-id', '375', '--raw', '--subdir', 'DAGS_FOLDER/censoEnade.py', '--cfg-path', '/tmp/tmpix7bzb20']
[2024-02-11T01:22:53.579+0000] {standard_task_runner.py:88} INFO - Job 375: Subtask convert_xlsx_to_csv
[2024-02-11T01:22:53.632+0000] {task_command.py:423} INFO - Running <TaskInstance: censoEnade.convert_xlsx_to_csv manual__2024-02-11T01:22:44.901787+00:00 [running]> on host 7e5b5e202339
[2024-02-11T01:22:53.729+0000] {taskinstance.py:2480} INFO - Exporting env vars: AIRFLOW_CTX_DAG_OWNER='NÃ©fi Fernandes' AIRFLOW_CTX_DAG_ID='censoEnade' AIRFLOW_CTX_TASK_ID='convert_xlsx_to_csv' AIRFLOW_CTX_EXECUTION_DATE='2024-02-11T01:22:44.901787+00:00' AIRFLOW_CTX_TRY_NUMBER='1' AIRFLOW_CTX_DAG_RUN_ID='manual__2024-02-11T01:22:44.901787+00:00'
[2024-02-11T01:22:53.734+0000] {taskinstance.py:2698} ERROR - Task failed with exception
Traceback (most recent call last):
  File "/home/airflow/.local/lib/python3.8/site-packages/airflow/models/taskinstance.py", line 433, in _execute_task
    result = execute_callable(context=context, **execute_callable_kwargs)
  File "/home/airflow/.local/lib/python3.8/site-packages/airflow/operators/python.py", line 199, in execute
    return_value = self.execute_callable()
  File "/home/airflow/.local/lib/python3.8/site-packages/airflow/operators/python.py", line 216, in execute_callable
    return self.python_callable(*self.op_args, **self.op_kwargs)
  File "/opt/airflow/dags/censoEnade.py", line 98, in convert_xlsx_to_csv
    df = pd.read_excel(input_file)
  File "/home/airflow/.local/lib/python3.8/site-packages/pandas/io/excel/_base.py", line 478, in read_excel
    io = ExcelFile(io, storage_options=storage_options, engine=engine)
  File "/home/airflow/.local/lib/python3.8/site-packages/pandas/io/excel/_base.py", line 1496, in __init__
    ext = inspect_excel_format(
  File "/home/airflow/.local/lib/python3.8/site-packages/pandas/io/excel/_base.py", line 1371, in inspect_excel_format
    with get_handle(
  File "/home/airflow/.local/lib/python3.8/site-packages/pandas/io/common.py", line 868, in get_handle
    handle = open(handle, ioargs.mode)
FileNotFoundError: [Errno 2] No such file or directory: 'C:/airflow-docker/dataset/diretorio_de_selecao/conceito_enade_2021.xlsx'
[2024-02-11T01:22:53.746+0000] {taskinstance.py:1138} INFO - Marking task as FAILED. dag_id=censoEnade, task_id=convert_xlsx_to_csv, execution_date=20240211T012244, start_date=20240211T012253, end_date=20240211T012253
[2024-02-11T01:22:53.765+0000] {standard_task_runner.py:107} ERROR - Failed to execute job 375 for task convert_xlsx_to_csv ([Errno 2] No such file or directory: 'C:/airflow-docker/dataset/diretorio_de_selecao/conceito_enade_2021.xlsx'; 458)
[2024-02-11T01:22:53.790+0000] {local_task_job_runner.py:234} INFO - Task exited with return code 1
[2024-02-11T01:22:53.811+0000] {taskinstance.py:3280} INFO - 0 downstream tasks scheduled from follow-on schedule check
