[2024-02-11T00:02:15.578+0000] {taskinstance.py:1956} INFO - Dependencies all met for dep_context=non-requeueable deps ti=<TaskInstance: censoEnade.extract_censo_2021 manual__2024-02-11T00:01:37.825370+00:00 [queued]>
[2024-02-11T00:02:15.589+0000] {taskinstance.py:1956} INFO - Dependencies all met for dep_context=requeueable deps ti=<TaskInstance: censoEnade.extract_censo_2021 manual__2024-02-11T00:01:37.825370+00:00 [queued]>
[2024-02-11T00:02:15.590+0000] {taskinstance.py:2170} INFO - Starting attempt 1 of 1
[2024-02-11T00:02:15.608+0000] {taskinstance.py:2191} INFO - Executing <Task(PythonOperator): extract_censo_2021> on 2024-02-11 00:01:37.825370+00:00
[2024-02-11T00:02:15.616+0000] {standard_task_runner.py:60} INFO - Started process 549 to run task
[2024-02-11T00:02:15.619+0000] {standard_task_runner.py:87} INFO - Running: ['***', 'tasks', 'run', 'censoEnade', 'extract_censo_2021', 'manual__2024-02-11T00:01:37.825370+00:00', '--job-id', '227', '--raw', '--subdir', 'DAGS_FOLDER/censoEnade.py', '--cfg-path', '/tmp/tmp13l0ppl6']
[2024-02-11T00:02:15.622+0000] {standard_task_runner.py:88} INFO - Job 227: Subtask extract_censo_2021
[2024-02-11T00:02:15.673+0000] {task_command.py:423} INFO - Running <TaskInstance: censoEnade.extract_censo_2021 manual__2024-02-11T00:01:37.825370+00:00 [running]> on host 7e5b5e202339
[2024-02-11T00:02:15.783+0000] {taskinstance.py:2480} INFO - Exporting env vars: AIRFLOW_CTX_DAG_OWNER='NÃ©fi Fernandes' AIRFLOW_CTX_DAG_ID='censoEnade' AIRFLOW_CTX_TASK_ID='extract_censo_2021' AIRFLOW_CTX_EXECUTION_DATE='2024-02-11T00:01:37.825370+00:00' AIRFLOW_CTX_TRY_NUMBER='1' AIRFLOW_CTX_DAG_RUN_ID='manual__2024-02-11T00:01:37.825370+00:00'
[2024-02-11T00:02:15.787+0000] {taskinstance.py:2698} ERROR - Task failed with exception
Traceback (most recent call last):
  File "/home/airflow/.local/lib/python3.8/site-packages/airflow/models/taskinstance.py", line 433, in _execute_task
    result = execute_callable(context=context, **execute_callable_kwargs)
  File "/home/airflow/.local/lib/python3.8/site-packages/airflow/operators/python.py", line 199, in execute
    return_value = self.execute_callable()
  File "/home/airflow/.local/lib/python3.8/site-packages/airflow/operators/python.py", line 216, in execute_callable
    return self.python_callable(*self.op_args, **self.op_kwargs)
  File "/opt/airflow/dags/censoEnade.py", line 60, in extract_zip_file
    with zipfile.ZipFile(zip_file_path, 'r') as zip_ref:
  File "/usr/local/lib/python3.8/zipfile.py", line 1251, in __init__
    self.fp = io.open(file, filemode)
FileNotFoundError: [Errno 2] No such file or directory: 'C:/airflow-docker/dataset/microdados_censo_da_educacao_superior_2021.zip'
[2024-02-11T00:02:15.801+0000] {taskinstance.py:1138} INFO - Marking task as FAILED. dag_id=censoEnade, task_id=extract_censo_2021, execution_date=20240211T000137, start_date=20240211T000215, end_date=20240211T000215
[2024-02-11T00:02:15.818+0000] {standard_task_runner.py:107} ERROR - Failed to execute job 227 for task extract_censo_2021 ([Errno 2] No such file or directory: 'C:/airflow-docker/dataset/microdados_censo_da_educacao_superior_2021.zip'; 549)
[2024-02-11T00:02:15.833+0000] {local_task_job_runner.py:234} INFO - Task exited with return code 1
[2024-02-11T00:02:15.883+0000] {taskinstance.py:3280} INFO - 0 downstream tasks scheduled from follow-on schedule check
