[2024-02-10T02:37:00.289+0000] {taskinstance.py:1956} INFO - Dependencies all met for dep_context=non-requeueable deps ti=<TaskInstance: censoEnade.convert_zip_file manual__2024-02-10T02:36:27.650129+00:00 [queued]>
[2024-02-10T02:37:00.312+0000] {taskinstance.py:1956} INFO - Dependencies all met for dep_context=requeueable deps ti=<TaskInstance: censoEnade.convert_zip_file manual__2024-02-10T02:36:27.650129+00:00 [queued]>
[2024-02-10T02:37:00.313+0000] {taskinstance.py:2170} INFO - Starting attempt 1 of 1
[2024-02-10T02:37:00.338+0000] {taskinstance.py:2191} INFO - Executing <Task(PythonOperator): convert_zip_file> on 2024-02-10 02:36:27.650129+00:00
[2024-02-10T02:37:00.347+0000] {standard_task_runner.py:60} INFO - Started process 177 to run task
[2024-02-10T02:37:00.351+0000] {standard_task_runner.py:87} INFO - Running: ['***', 'tasks', 'run', 'censoEnade', 'convert_zip_file', 'manual__2024-02-10T02:36:27.650129+00:00', '--job-id', '151', '--raw', '--subdir', 'DAGS_FOLDER/censoEnade.py', '--cfg-path', '/tmp/tmpplzqz7mq']
[2024-02-10T02:37:00.354+0000] {standard_task_runner.py:88} INFO - Job 151: Subtask convert_zip_file
[2024-02-10T02:37:00.421+0000] {task_command.py:423} INFO - Running <TaskInstance: censoEnade.convert_zip_file manual__2024-02-10T02:36:27.650129+00:00 [running]> on host 7e5b5e202339
[2024-02-10T02:37:00.524+0000] {taskinstance.py:2480} INFO - Exporting env vars: AIRFLOW_CTX_DAG_OWNER='NÃ©fi Fernandes' AIRFLOW_CTX_DAG_ID='censoEnade' AIRFLOW_CTX_TASK_ID='convert_zip_file' AIRFLOW_CTX_EXECUTION_DATE='2024-02-10T02:36:27.650129+00:00' AIRFLOW_CTX_TRY_NUMBER='1' AIRFLOW_CTX_DAG_RUN_ID='manual__2024-02-10T02:36:27.650129+00:00'
[2024-02-10T02:37:00.527+0000] {taskinstance.py:2698} ERROR - Task failed with exception
Traceback (most recent call last):
  File "/home/airflow/.local/lib/python3.8/site-packages/airflow/models/taskinstance.py", line 433, in _execute_task
    result = execute_callable(context=context, **execute_callable_kwargs)
  File "/home/airflow/.local/lib/python3.8/site-packages/airflow/operators/python.py", line 199, in execute
    return_value = self.execute_callable()
  File "/home/airflow/.local/lib/python3.8/site-packages/airflow/operators/python.py", line 216, in execute_callable
    return self.python_callable(*self.op_args, **self.op_kwargs)
TypeError: convert_7z_to_zip() missing 2 required positional arguments: 'archive_path' and 'output_dir'
[2024-02-10T02:37:00.537+0000] {taskinstance.py:1138} INFO - Marking task as FAILED. dag_id=censoEnade, task_id=convert_zip_file, execution_date=20240210T023627, start_date=20240210T023700, end_date=20240210T023700
[2024-02-10T02:37:00.554+0000] {standard_task_runner.py:107} ERROR - Failed to execute job 151 for task convert_zip_file (convert_7z_to_zip() missing 2 required positional arguments: 'archive_path' and 'output_dir'; 177)
[2024-02-10T02:37:00.563+0000] {local_task_job_runner.py:234} INFO - Task exited with return code 1
[2024-02-10T02:37:00.592+0000] {taskinstance.py:3280} INFO - 0 downstream tasks scheduled from follow-on schedule check
