[2024-02-07T00:32:44.903+0000] {taskinstance.py:1956} INFO - Dependencies all met for dep_context=non-requeueable deps ti=<TaskInstance: censoEnade.processamento_csv manual__2024-02-07T00:32:42.858790+00:00 [queued]>
[2024-02-07T00:32:44.917+0000] {taskinstance.py:1956} INFO - Dependencies all met for dep_context=requeueable deps ti=<TaskInstance: censoEnade.processamento_csv manual__2024-02-07T00:32:42.858790+00:00 [queued]>
[2024-02-07T00:32:44.918+0000] {taskinstance.py:2170} INFO - Starting attempt 1 of 1
[2024-02-07T00:32:44.942+0000] {taskinstance.py:2191} INFO - Executing <Task(PythonOperator): processamento_csv> on 2024-02-07 00:32:42.858790+00:00
[2024-02-07T00:32:44.951+0000] {standard_task_runner.py:60} INFO - Started process 1329 to run task
[2024-02-07T00:32:44.958+0000] {standard_task_runner.py:87} INFO - Running: ['***', 'tasks', 'run', 'censoEnade', 'processamento_csv', 'manual__2024-02-07T00:32:42.858790+00:00', '--job-id', '55', '--raw', '--subdir', 'DAGS_FOLDER/censoEnade.py', '--cfg-path', '/tmp/tmpyt_qrhvu']
[2024-02-07T00:32:44.961+0000] {standard_task_runner.py:88} INFO - Job 55: Subtask processamento_csv
[2024-02-07T00:32:45.026+0000] {task_command.py:423} INFO - Running <TaskInstance: censoEnade.processamento_csv manual__2024-02-07T00:32:42.858790+00:00 [running]> on host 113c724a1462
[2024-02-07T00:32:45.125+0000] {taskinstance.py:2480} INFO - Exporting env vars: AIRFLOW_CTX_DAG_OWNER='NÃ©fi Fernandes' AIRFLOW_CTX_DAG_ID='censoEnade' AIRFLOW_CTX_TASK_ID='processamento_csv' AIRFLOW_CTX_EXECUTION_DATE='2024-02-07T00:32:42.858790+00:00' AIRFLOW_CTX_TRY_NUMBER='1' AIRFLOW_CTX_DAG_RUN_ID='manual__2024-02-07T00:32:42.858790+00:00'
[2024-02-07T00:32:45.130+0000] {taskinstance.py:2698} ERROR - Task failed with exception
Traceback (most recent call last):
  File "/home/airflow/.local/lib/python3.8/site-packages/airflow/models/taskinstance.py", line 433, in _execute_task
    result = execute_callable(context=context, **execute_callable_kwargs)
  File "/home/airflow/.local/lib/python3.8/site-packages/airflow/operators/python.py", line 199, in execute
    return_value = self.execute_callable()
  File "/home/airflow/.local/lib/python3.8/site-packages/airflow/operators/python.py", line 216, in execute_callable
    return self.python_callable(*self.op_args, **self.op_kwargs)
  File "/opt/airflow/dags/censoEnade.py", line 37, in processar_arquivo_csv
    pd.read_csv(
  File "/home/airflow/.local/lib/python3.8/site-packages/pandas/io/parsers/readers.py", line 912, in read_csv
    return _read(filepath_or_buffer, kwds)
  File "/home/airflow/.local/lib/python3.8/site-packages/pandas/io/parsers/readers.py", line 577, in _read
    parser = TextFileReader(filepath_or_buffer, **kwds)
  File "/home/airflow/.local/lib/python3.8/site-packages/pandas/io/parsers/readers.py", line 1407, in __init__
    self._engine = self._make_engine(f, self.engine)
  File "/home/airflow/.local/lib/python3.8/site-packages/pandas/io/parsers/readers.py", line 1661, in _make_engine
    self.handles = get_handle(
  File "/home/airflow/.local/lib/python3.8/site-packages/pandas/io/common.py", line 859, in get_handle
    handle = open(
FileNotFoundError: [Errno 2] No such file or directory: 'C:/airflow-docker/dataset/microdados2022_arq1.txt'
[2024-02-07T00:32:45.143+0000] {taskinstance.py:1138} INFO - Marking task as FAILED. dag_id=censoEnade, task_id=processamento_csv, execution_date=20240207T003242, start_date=20240207T003244, end_date=20240207T003245
[2024-02-07T00:32:45.160+0000] {standard_task_runner.py:107} ERROR - Failed to execute job 55 for task processamento_csv ([Errno 2] No such file or directory: 'C:/airflow-docker/dataset/microdados2022_arq1.txt'; 1329)
[2024-02-07T00:32:45.170+0000] {local_task_job_runner.py:234} INFO - Task exited with return code 1
[2024-02-07T00:32:45.191+0000] {taskinstance.py:3280} INFO - 0 downstream tasks scheduled from follow-on schedule check
