[2024-02-11T00:34:53.203+0000] {taskinstance.py:1956} INFO - Dependencies all met for dep_context=non-requeueable deps ti=<TaskInstance: censoEnade.select_conceito_2021 manual__2024-02-11T00:34:44.631745+00:00 [queued]>
[2024-02-11T00:34:53.219+0000] {taskinstance.py:1956} INFO - Dependencies all met for dep_context=requeueable deps ti=<TaskInstance: censoEnade.select_conceito_2021 manual__2024-02-11T00:34:44.631745+00:00 [queued]>
[2024-02-11T00:34:53.221+0000] {taskinstance.py:2170} INFO - Starting attempt 1 of 1
[2024-02-11T00:34:53.245+0000] {taskinstance.py:2191} INFO - Executing <Task(PythonOperator): select_conceito_2021> on 2024-02-11 00:34:44.631745+00:00
[2024-02-11T00:34:53.255+0000] {standard_task_runner.py:60} INFO - Started process 1105 to run task
[2024-02-11T00:34:53.258+0000] {standard_task_runner.py:87} INFO - Running: ['***', 'tasks', 'run', 'censoEnade', 'select_conceito_2021', 'manual__2024-02-11T00:34:44.631745+00:00', '--job-id', '253', '--raw', '--subdir', 'DAGS_FOLDER/censoEnade.py', '--cfg-path', '/tmp/tmpbipwxe15']
[2024-02-11T00:34:53.260+0000] {standard_task_runner.py:88} INFO - Job 253: Subtask select_conceito_2021
[2024-02-11T00:34:53.327+0000] {task_command.py:423} INFO - Running <TaskInstance: censoEnade.select_conceito_2021 manual__2024-02-11T00:34:44.631745+00:00 [running]> on host 7e5b5e202339
[2024-02-11T00:34:53.443+0000] {taskinstance.py:2480} INFO - Exporting env vars: AIRFLOW_CTX_DAG_OWNER='NÃ©fi Fernandes' AIRFLOW_CTX_DAG_ID='censoEnade' AIRFLOW_CTX_TASK_ID='select_conceito_2021' AIRFLOW_CTX_EXECUTION_DATE='2024-02-11T00:34:44.631745+00:00' AIRFLOW_CTX_TRY_NUMBER='1' AIRFLOW_CTX_DAG_RUN_ID='manual__2024-02-11T00:34:44.631745+00:00'
[2024-02-11T00:34:53.445+0000] {taskinstance.py:2698} ERROR - Task failed with exception
Traceback (most recent call last):
  File "/home/airflow/.local/lib/python3.8/site-packages/airflow/models/taskinstance.py", line 433, in _execute_task
    result = execute_callable(context=context, **execute_callable_kwargs)
  File "/home/airflow/.local/lib/python3.8/site-packages/airflow/operators/python.py", line 199, in execute
    return_value = self.execute_callable()
  File "/home/airflow/.local/lib/python3.8/site-packages/airflow/operators/python.py", line 216, in execute_callable
    return self.python_callable(*self.op_args, **self.op_kwargs)
TypeError: select_data_from_xlsx() missing 1 required positional argument: 'columns'
[2024-02-11T00:34:53.454+0000] {taskinstance.py:1138} INFO - Marking task as FAILED. dag_id=censoEnade, task_id=select_conceito_2021, execution_date=20240211T003444, start_date=20240211T003453, end_date=20240211T003453
[2024-02-11T00:34:53.471+0000] {standard_task_runner.py:107} ERROR - Failed to execute job 253 for task select_conceito_2021 (select_data_from_xlsx() missing 1 required positional argument: 'columns'; 1105)
[2024-02-11T00:34:53.511+0000] {local_task_job_runner.py:234} INFO - Task exited with return code 1
[2024-02-11T00:34:53.530+0000] {taskinstance.py:3280} INFO - 0 downstream tasks scheduled from follow-on schedule check
