[2024-02-11T01:10:24.170+0000] {taskinstance.py:1956} INFO - Dependencies all met for dep_context=non-requeueable deps ti=<TaskInstance: censoEnade.select_conceito_2021 manual__2024-02-11T01:10:15.852248+00:00 [queued]>
[2024-02-11T01:10:24.184+0000] {taskinstance.py:1956} INFO - Dependencies all met for dep_context=requeueable deps ti=<TaskInstance: censoEnade.select_conceito_2021 manual__2024-02-11T01:10:15.852248+00:00 [queued]>
[2024-02-11T01:10:24.185+0000] {taskinstance.py:2170} INFO - Starting attempt 1 of 1
[2024-02-11T01:10:24.210+0000] {taskinstance.py:2191} INFO - Executing <Task(PythonOperator): select_conceito_2021> on 2024-02-11 01:10:15.852248+00:00
[2024-02-11T01:10:24.219+0000] {standard_task_runner.py:60} INFO - Started process 165 to run task
[2024-02-11T01:10:24.222+0000] {standard_task_runner.py:87} INFO - Running: ['***', 'tasks', 'run', 'censoEnade', 'select_conceito_2021', 'manual__2024-02-11T01:10:15.852248+00:00', '--job-id', '340', '--raw', '--subdir', 'DAGS_FOLDER/censoEnade.py', '--cfg-path', '/tmp/tmpcco7_ivv']
[2024-02-11T01:10:24.224+0000] {standard_task_runner.py:88} INFO - Job 340: Subtask select_conceito_2021
[2024-02-11T01:10:24.282+0000] {task_command.py:423} INFO - Running <TaskInstance: censoEnade.select_conceito_2021 manual__2024-02-11T01:10:15.852248+00:00 [running]> on host 7e5b5e202339
[2024-02-11T01:10:24.380+0000] {taskinstance.py:2480} INFO - Exporting env vars: AIRFLOW_CTX_DAG_OWNER='NÃ©fi Fernandes' AIRFLOW_CTX_DAG_ID='censoEnade' AIRFLOW_CTX_TASK_ID='select_conceito_2021' AIRFLOW_CTX_EXECUTION_DATE='2024-02-11T01:10:15.852248+00:00' AIRFLOW_CTX_TRY_NUMBER='1' AIRFLOW_CTX_DAG_RUN_ID='manual__2024-02-11T01:10:15.852248+00:00'
[2024-02-11T01:10:24.640+0000] {taskinstance.py:2698} ERROR - Task failed with exception
Traceback (most recent call last):
  File "/home/airflow/.local/lib/python3.8/site-packages/airflow/models/taskinstance.py", line 433, in _execute_task
    result = execute_callable(context=context, **execute_callable_kwargs)
  File "/home/airflow/.local/lib/python3.8/site-packages/airflow/operators/python.py", line 199, in execute
    return_value = self.execute_callable()
  File "/home/airflow/.local/lib/python3.8/site-packages/airflow/operators/python.py", line 216, in execute_callable
    return self.python_callable(*self.op_args, **self.op_kwargs)
  File "/opt/airflow/dags/censoEnade.py", line 92, in select_data_from_xlsx
    df = pd.read_excel(input_file, sheet_name=sheet_name)
  File "/home/airflow/.local/lib/python3.8/site-packages/pandas/io/excel/_base.py", line 486, in read_excel
    data = io.parse(
  File "/home/airflow/.local/lib/python3.8/site-packages/pandas/io/excel/_base.py", line 1551, in parse
    return self._reader.parse(
  File "/home/airflow/.local/lib/python3.8/site-packages/pandas/io/excel/_base.py", line 746, in parse
    sheet = self.get_sheet_by_name(asheetname)
  File "/home/airflow/.local/lib/python3.8/site-packages/pandas/io/excel/_openpyxl.py", line 569, in get_sheet_by_name
    self.raise_if_bad_sheet_by_name(name)
  File "/home/airflow/.local/lib/python3.8/site-packages/pandas/io/excel/_base.py", line 597, in raise_if_bad_sheet_by_name
    raise ValueError(f"Worksheet named '{name}' not found")
ValueError: Worksheet named 'conceito_enade_2021.xlsx' not found
[2024-02-11T01:10:24.654+0000] {taskinstance.py:1138} INFO - Marking task as FAILED. dag_id=censoEnade, task_id=select_conceito_2021, execution_date=20240211T011015, start_date=20240211T011024, end_date=20240211T011024
[2024-02-11T01:10:24.672+0000] {standard_task_runner.py:107} ERROR - Failed to execute job 340 for task select_conceito_2021 (Worksheet named 'conceito_enade_2021.xlsx' not found; 165)
[2024-02-11T01:10:24.716+0000] {local_task_job_runner.py:234} INFO - Task exited with return code 1
[2024-02-11T01:10:24.734+0000] {taskinstance.py:3280} INFO - 0 downstream tasks scheduled from follow-on schedule check
