[2024-02-11T01:24:19.568+0000] {taskinstance.py:1956} INFO - Dependencies all met for dep_context=non-requeueable deps ti=<TaskInstance: censoEnade.convert_xlsx_to_csv manual__2024-02-11T01:24:11.887773+00:00 [queued]>
[2024-02-11T01:24:19.579+0000] {taskinstance.py:1956} INFO - Dependencies all met for dep_context=requeueable deps ti=<TaskInstance: censoEnade.convert_xlsx_to_csv manual__2024-02-11T01:24:11.887773+00:00 [queued]>
[2024-02-11T01:24:19.580+0000] {taskinstance.py:2170} INFO - Starting attempt 1 of 1
[2024-02-11T01:24:19.600+0000] {taskinstance.py:2191} INFO - Executing <Task(PythonOperator): convert_xlsx_to_csv> on 2024-02-11 01:24:11.887773+00:00
[2024-02-11T01:24:19.607+0000] {standard_task_runner.py:60} INFO - Started process 505 to run task
[2024-02-11T01:24:19.614+0000] {standard_task_runner.py:87} INFO - Running: ['***', 'tasks', 'run', 'censoEnade', 'convert_xlsx_to_csv', 'manual__2024-02-11T01:24:11.887773+00:00', '--job-id', '385', '--raw', '--subdir', 'DAGS_FOLDER/censoEnade.py', '--cfg-path', '/tmp/tmpqrlgbp7r']
[2024-02-11T01:24:19.615+0000] {standard_task_runner.py:88} INFO - Job 385: Subtask convert_xlsx_to_csv
[2024-02-11T01:24:19.669+0000] {task_command.py:423} INFO - Running <TaskInstance: censoEnade.convert_xlsx_to_csv manual__2024-02-11T01:24:11.887773+00:00 [running]> on host 7e5b5e202339
[2024-02-11T01:24:19.769+0000] {taskinstance.py:2480} INFO - Exporting env vars: AIRFLOW_CTX_DAG_OWNER='NÃ©fi Fernandes' AIRFLOW_CTX_DAG_ID='censoEnade' AIRFLOW_CTX_TASK_ID='convert_xlsx_to_csv' AIRFLOW_CTX_EXECUTION_DATE='2024-02-11T01:24:11.887773+00:00' AIRFLOW_CTX_TRY_NUMBER='1' AIRFLOW_CTX_DAG_RUN_ID='manual__2024-02-11T01:24:11.887773+00:00'
[2024-02-11T01:24:22.564+0000] {taskinstance.py:2698} ERROR - Task failed with exception
Traceback (most recent call last):
  File "/home/airflow/.local/lib/python3.8/site-packages/airflow/models/taskinstance.py", line 433, in _execute_task
    result = execute_callable(context=context, **execute_callable_kwargs)
  File "/home/airflow/.local/lib/python3.8/site-packages/airflow/operators/python.py", line 199, in execute
    return_value = self.execute_callable()
  File "/home/airflow/.local/lib/python3.8/site-packages/airflow/operators/python.py", line 216, in execute_callable
    return self.python_callable(*self.op_args, **self.op_kwargs)
  File "/opt/airflow/dags/censoEnade.py", line 99, in convert_xlsx_to_csv
    df.to_csv(output_file, index=False)
  File "/home/airflow/.local/lib/python3.8/site-packages/pandas/core/generic.py", line 3772, in to_csv
    return DataFrameRenderer(formatter).to_csv(
  File "/home/airflow/.local/lib/python3.8/site-packages/pandas/io/formats/format.py", line 1186, in to_csv
    csv_formatter.save()
  File "/home/airflow/.local/lib/python3.8/site-packages/pandas/io/formats/csvs.py", line 240, in save
    with get_handle(
  File "/home/airflow/.local/lib/python3.8/site-packages/pandas/io/common.py", line 737, in get_handle
    check_parent_directory(str(handle))
  File "/home/airflow/.local/lib/python3.8/site-packages/pandas/io/common.py", line 600, in check_parent_directory
    raise OSError(rf"Cannot save file into a non-existent directory: '{parent}'")
OSError: Cannot save file into a non-existent directory: 'C:/***-docker/dataset/diretorio_de_selecao'
[2024-02-11T01:24:22.585+0000] {taskinstance.py:1138} INFO - Marking task as FAILED. dag_id=censoEnade, task_id=convert_xlsx_to_csv, execution_date=20240211T012411, start_date=20240211T012419, end_date=20240211T012422
[2024-02-11T01:24:22.601+0000] {standard_task_runner.py:107} ERROR - Failed to execute job 385 for task convert_xlsx_to_csv (Cannot save file into a non-existent directory: 'C:/***-docker/dataset/diretorio_de_selecao'; 505)
[2024-02-11T01:24:22.637+0000] {local_task_job_runner.py:234} INFO - Task exited with return code 1
[2024-02-11T01:24:22.655+0000] {taskinstance.py:3280} INFO - 0 downstream tasks scheduled from follow-on schedule check
