[2024-02-11T01:25:07.721+0000] {taskinstance.py:1956} INFO - Dependencies all met for dep_context=non-requeueable deps ti=<TaskInstance: censoEnade.convert_txt_to_csv manual__2024-02-11T01:24:11.887773+00:00 [queued]>
[2024-02-11T01:25:07.736+0000] {taskinstance.py:1956} INFO - Dependencies all met for dep_context=requeueable deps ti=<TaskInstance: censoEnade.convert_txt_to_csv manual__2024-02-11T01:24:11.887773+00:00 [queued]>
[2024-02-11T01:25:07.736+0000] {taskinstance.py:2170} INFO - Starting attempt 1 of 1
[2024-02-11T01:25:07.760+0000] {taskinstance.py:2191} INFO - Executing <Task(PythonOperator): convert_txt_to_csv> on 2024-02-11 01:24:11.887773+00:00
[2024-02-11T01:25:07.767+0000] {standard_task_runner.py:60} INFO - Started process 545 to run task
[2024-02-11T01:25:07.771+0000] {standard_task_runner.py:87} INFO - Running: ['***', 'tasks', 'run', 'censoEnade', 'convert_txt_to_csv', 'manual__2024-02-11T01:24:11.887773+00:00', '--job-id', '391', '--raw', '--subdir', 'DAGS_FOLDER/censoEnade.py', '--cfg-path', '/tmp/tmp6m2zvo78']
[2024-02-11T01:25:07.773+0000] {standard_task_runner.py:88} INFO - Job 391: Subtask convert_txt_to_csv
[2024-02-11T01:25:07.832+0000] {task_command.py:423} INFO - Running <TaskInstance: censoEnade.convert_txt_to_csv manual__2024-02-11T01:24:11.887773+00:00 [running]> on host 7e5b5e202339
[2024-02-11T01:25:07.932+0000] {taskinstance.py:2480} INFO - Exporting env vars: AIRFLOW_CTX_DAG_OWNER='NÃ©fi Fernandes' AIRFLOW_CTX_DAG_ID='censoEnade' AIRFLOW_CTX_TASK_ID='convert_txt_to_csv' AIRFLOW_CTX_EXECUTION_DATE='2024-02-11T01:24:11.887773+00:00' AIRFLOW_CTX_TRY_NUMBER='1' AIRFLOW_CTX_DAG_RUN_ID='manual__2024-02-11T01:24:11.887773+00:00'
[2024-02-11T01:25:07.933+0000] {taskinstance.py:2698} ERROR - Task failed with exception
Traceback (most recent call last):
  File "/home/airflow/.local/lib/python3.8/site-packages/airflow/models/taskinstance.py", line 433, in _execute_task
    result = execute_callable(context=context, **execute_callable_kwargs)
  File "/home/airflow/.local/lib/python3.8/site-packages/airflow/operators/python.py", line 199, in execute
    return_value = self.execute_callable()
  File "/home/airflow/.local/lib/python3.8/site-packages/airflow/operators/python.py", line 216, in execute_callable
    return self.python_callable(*self.op_args, **self.op_kwargs)
  File "/opt/airflow/dags/censoEnade.py", line 91, in convert_txt_to_csv
    with open(input_file, 'r') as txt_file, open(output_file, 'w', newline='') as csv_file:
FileNotFoundError: [Errno 2] No such file or directory: 'C:/airflow-docker/dataset/diretorio_de_selecao/microdados2021_arq1.txt'
[2024-02-11T01:25:07.947+0000] {taskinstance.py:1138} INFO - Marking task as FAILED. dag_id=censoEnade, task_id=convert_txt_to_csv, execution_date=20240211T012411, start_date=20240211T012507, end_date=20240211T012507
[2024-02-11T01:25:07.966+0000] {standard_task_runner.py:107} ERROR - Failed to execute job 391 for task convert_txt_to_csv ([Errno 2] No such file or directory: 'C:/airflow-docker/dataset/diretorio_de_selecao/microdados2021_arq1.txt'; 545)
[2024-02-11T01:25:07.983+0000] {local_task_job_runner.py:234} INFO - Task exited with return code 1
[2024-02-11T01:25:08.005+0000] {taskinstance.py:3280} INFO - 0 downstream tasks scheduled from follow-on schedule check
